Workbook

Sheet 下载
C1: Công ty TNHH Pegatron Việt Nam PEGATRON VIETNAM Co.Ltd
A3: BÁO CÁO CHI TIẾT
A4: DETAIL REPORT
B6: Từ ngày (From): | C6: 2026/06/16 | D6: Đến ngày (To): | E6: 2026/06/16 | F6: Khu vực (Zone): | G6: All | H6: Đồng hồ (Meter): | I6: All
A8: # | B8: Thời gian | C8: Chỉ số đầu Start indicator | D8: Chỉ số cuối Finish indicator | E8: Năng lượng tiêu thụ Consumption (KWh) | F8: Cao điểm Rush hour (KWh) | G8: Bình thường Normal (KWh) | H8: Thấp điểm Off-rush hour (KWh) | I8: Điện áp LL Voltage LL (V) | J8: Điện áp LL Voltage LL (V) | K8: Dòng điện Current (A) | L8: Công suất Power (KW) | M8: Cosphi (%)
B9: Meter: F1P12 | C9: 130068.9 | D9: 130076.4 | E9: 7.5 | F9: 0 | G9: 7.5 | H9: 0
A10: 1 | B10: 46189.333 | E10: 7.5 | F10: 0 | G10: 7.5 | H10: 0 | I10: 390.8 | J10: 225.6 | K10: 14.8 | L10: 7.7 | M10: 92.6
B11: Meter: F1MAC31 | C11: 2221594.1 | D11: 2221717.2 | E11: 123.1 | F11: 0 | G11: 123.1 | H11: 0
A12: 1 | B12: 46189.333 | E12: 123.1 | F12: 0 | G12: 123.1 | H12: 0 | I12: 390.4 | J12: 225.5 | K12: 202.2 | L12: 123.5 | M12: 96.8
B13: Meter: F1MP22-1 | C13: 669399.5 | D13: 669484.6 | E13: 85.1 | F13: 0 | G13: 85.1 | H13: 0
A14: 1 | B14: 46189.333 | E14: 85.1 | F14: 0 | G14: 85.1 | H14: 0 | I14: 394.3 | J14: 227.7 | K14: 133.6 | L14: 85.8 | M14: 99.5
B15: Meter: F1P12-1 | C15: 86721.5 | D15: 86721.5 | E15: 0 | F15: 0 | G15: 0 | H15: 0
A16: 1 | B16: 46189.333 | E16: 0 | F16: 0 | G16: 0 | H16: 0 | I16: 390.7 | J16: 225.6 | K16: 0 | L16: 0 | M16: 100
B17: Meter: F1AC31 | C17: 214964.9 | D17: 214989.4 | E17: 24.5 | F17: 0 | G17: 24.5 | H17: 0
A18: 1 | B18: 46189.333 | E18: 24.5 | F18: 0 | G18: 24.5 | H18: 0 | I18: 390.3 | J18: 225.3 | K18: 40.3 | L18: 24.6 | M18: 98.8
B19: Meter: F1MP23-1 | C19: 169262.7 | D19: 169278.2 | E19: 15.5 | F19: 0 | G19: 15.5 | H19: 0
A20: 1 | B20: 46189.333 | E20: 15.5 | F20: 0 | G20: 15.5 | H20: 0 | I20: 394.3 | J20: 227.6 | K20: 24.5 | L20: 15.2 | M20: 98.9
B21: Meter: F1P12-2 | C21: 39071 | D21: 39076.6 | E21: 5.6 | F21: 0 | G21: 5.6 | H21: 0
A22: 1 | B22: 46189.333 | E22: 5.6 | F22: 0 | G22: 5.6 | H22: 0 | I22: 390.7 | J22: 225.6 | K22: 11.6 | L22: 5.6 | M22: 97.6
B23: Meter: F1AC32 | C23: 325900.4 | D23: 325926.1 | E23: 25.7 | F23: 0 | G23: 25.7 | H23: 0
A24: 1 | B24: 46189.333 | E24: 25.7 | F24: 0 | G24: 25.7 | H24: 0 | I24: 390.3 | J24: 225.4 | K24: 41.8 | L24: 25.7 | M24: 99.3
B25: Meter: F1MP24-1 | C25: 1224989.3 | D25: 1225096.9 | E25: 107.6 | F25: 0 | G25: 107.6 | H25: 0
A26: 1 | B26: 46189.333 | E26: 107.6 | F26: 0 | G26: 107.6 | H26: 0 | I26: 394.2 | J26: 227.6 | K26: 158.2 | L26: 105.8 | M26: 100
B27: Meter: F1P12-3 | C27: 5370.4 | D27: 5372.4 | E27: 2 | F27: 0 | G27: 2 | H27: 0
A28: 1 | B28: 46189.333 | E28: 2 | F28: 0 | G28: 2 | H28: 0 | I28: 390.9 | J28: 225.7 | K28: 4 | L28: 1.9 | M28: 72.5
B29: Meter: F1AC33 | C29: 383579.1 | D29: 383602.8 | E29: 23.7 | F29: 0 | G29: 23.7 | H29: 0
A30: 1 | B30: 46189.333 | E30: 23.7 | F30: 0 | G30: 23.7 | H30: 0 | I30: 390.3 | J30: 225.4 | K30: 39.5 | L30: 23.8 | M30: 98.8
B31: Meter: F1MP24-2 | C31: 2243708 | D31: 2243835.4 | E31: 127.4 | F31: 0 | G31: 127.4 | H31: 0
A32: 1 | B32: 46189.333 | E32: 127.4 | F32: 0 | G32: 127.4 | H32: 0 | I32: 394.2 | J32: 227.6 | K32: 202.8 | L32: 125.1 | M32: 96.4
B33: Meter: F1AC34 | C33: 256185.2 | D33: 256195 | E33: 9.8 | F33: 0 | G33: 9.8 | H33: 0
A34: 1 | B34: 46189.333 | E34: 9.8 | F34: 0 | G34: 9.8 | H34: 0 | I34: 390.4 | J34: 225.4 | K34: 18.1 | L34: 9.8 | M34: 99.2
B35: Meter: F1MP24-3 | C35: 412301.8 | D35: 412318.2 | E35: 16.4 | F35: 0 | G35: 16.4 | H35: 0
A36: 1 | B36: 46189.333 | E36: 16.4 | F36: 0 | G36: 16.4 | H36: 0 | I36: 394.3 | J36: 227.7 | K36: 25 | L36: 16.1 | M36: 95.5
B37: Meter: F1ACR1 | C37: 174072.1 | D37: 174078.4 | E37: 6.3 | F37: 0 | G37: 6.3 | H37: 0
A38: 1 | B38: 46189.333 | E38: 6.3 | F38: 0 | G38: 6.3 | H38: 0 | I38: 390.3 | J38: 225.4 | K38: 14.7 | L38: 6.3 | M38: 63.5
B39: Meter: F1ML11 | C39: 1077431.5 | D39: 1077493.6 | E39: 62.1 | F39: 0 | G39: 62.1 | H39: 0
A40: 1 | B40: 46189.333 | E40: 62.1 | F40: 0 | G40: 62.1 | H40: 0 | I40: 390.1 | J40: 225.2 | K40: 95.1 | L40: 62 | M40: 99.2
B41: Meter: F1ACR2 | C41: 109866.8 | D41: 109871.2 | E41: 4.4 | F41: 0 | G41: 4.4 | H41: 0
A42: 1 | B42: 46189.333 | E42: 4.4 | F42: 0 | G42: 4.4 | H42: 0 | I42: 390.4 | J42: 225.4 | K42: 7.5 | L42: 4.4 | M42: 90.7
B43: Meter: F1L11 | C43: 271997.2 | D43: 272010 | E43: 12.8 | F43: 0 | G43: 12.8 | H43: 0
...

Sheet 每日下载读数
B1: 08：00-08：00 | D1: 每日读数
A2: F1-1F照明插座 (ổ cắm, chiếu sáng) | C2: F1L11 | D2: =VLOOKUP("*"&C2,下载!B:C,2,0) -> 271997.2
C3: F1L12 | D3: =VLOOKUP("*"&C3,下载!B:C,2,0) -> 156136.6
C4: F1EL11 | D4: =VLOOKUP("*"&C4,下载!B:C,2,0) -> 74606.7
C5: F1EL12 | D5: =VLOOKUP("*"&C5,下载!B:C,2,0) -> 53629.5
C6: F1PZ11 | D6: =VLOOKUP("*"&C6,下载!B:C,2,0) -> 36797.1
A7: F1-2F照明插座 | C7: F1L21 | D7: =VLOOKUP("*"&C7,下载!B:C,2,0) -> 25892.9
C8: F1EL21 | D8: =VLOOKUP("*"&C8,下载!B:C,2,0) -> 2989.5
C9: F1PZ21 | D9: =VLOOKUP("*"&C9,下载!B:C,2,0) -> 9493.7
A10: F1-3F照明插座 | C10: F1L31 | D10: =VLOOKUP("*"&C10,下载!B:C,2,0) -> 188000
C11: F1EL31 | D11: =VLOOKUP("*"&C11,下载!B:C,2,0) -> 56407.5
C12: F1PZ31 | D12: =VLOOKUP("*"&C12,下载!B:C,2,0) -> 18610.4
C13: F1L32 | D13: =VLOOKUP("*"&C13,下载!B:C,2,0) -> 144468.9
C14: F1EL32 | D14: =VLOOKUP("*"&C14,下载!B:C,2,0) -> 66272.8
C15: F1PZ32 | D15: =VLOOKUP("*"&C15,下载!B:C,2,0) -> 25583.9
A16: F2-1F照明插座 | C16: F2L11 | D16: =VLOOKUP("*"&C16,下载!B:C,2,0) -> 239664.1
C17: F2L12 | D17: =VLOOKUP("*"&C17,下载!B:C,2,0) -> 290474.4
C18: F2EL11 | D18: =VLOOKUP("*"&C18,下载!B:C,2,0) -> 88015.5
C19: F2EL12 | D19: =VLOOKUP("*"&C19,下载!B:C,2,0) -> 80514.8
C20: F2PZ11 | D20: =VLOOKUP("*"&C20,下载!B:C,2,0) -> 31487.7
A21: F2-2F照明插座 | C21: F2EL21 | D21: =VLOOKUP("*"&C21,下载!B:C,2,0) -> 79394.1
C22: F2L21 | D22: =VLOOKUP("*"&C22,下载!B:C,2,0) -> 311386.9
C23: F2L22 | D23: =VLOOKUP("*"&C23,下载!B:C,2,0) -> 234845.2
C24: F2EL22 | D24: =VLOOKUP("*"&C24,下载!B:C,2,0) -> 21897
C25: F2PZ21 | D25: =VLOOKUP("*"&C25,下载!B:C,2,0) -> 41469.9
C26: F2PZ22 | D26: =VLOOKUP("*"&C26,下载!B:C,2,0) -> 25948.5
A27: F2-3F照明插座 | C27: F2L31 | D27: =VLOOKUP("*"&C27,下载!B:C,2,0) -> 239187.9
C28: F2EL31 | D28: =VLOOKUP("*"&C28,下载!B:C,2,0) -> 23264
C29: F2PZ31 | D29: =VLOOKUP("*"&C29,下载!B:C,2,0) -> 25403.9
C30: F2L32 | D30: =VLOOKUP("*"&C30,下载!B:C,2,0) -> 845.7
C31: F2EL32 | D31: =VLOOKUP("*"&C31,下载!B:C,2,0) -> 20605
C32: F2PZ32 | D32: =VLOOKUP("*"&C32,下载!B:C,2,0) -> 24824.8
A33: KD1-1F照明插座 | C33: KD1EL11 | D33: =VLOOKUP("*"&C33,下载!B:C,2,0) -> 30568.6
C34: KD1EL12 | D34: =VLOOKUP("*"&C34,下载!B:C,2,0) -> 30175.1
C35: KD1PZ11 | D35: =VLOOKUP("*"&C35,下载!B:C,2,0) -> 14875.8
A36: KD1-2F照明插座 | C36: KD1EL21 | D36: =VLOOKUP("*"&C36,下载!B:C,2,0) -> 108591.4
C37: KD1PZ21 | D37: =VLOOKUP("*"&C37,下载!B:C,2,0) -> 14883.2
A38: Quạt hút (roof) | B38: F2-PFR1 | C38: F2P31-2 | D38: =VLOOKUP("*"&C38,下载!B:C,2,0) -> 643643
B39: F1PYR2 | C39: MP-EXF-01 | D39: =VLOOKUP("*"&C39,下载!B:C,2,0) -> #N/A
B40: F2PYR2 | C40: MP-EXF-02 | D40: =VLOOKUP("*"&C40,下载!B:C,2,0) -> #N/A
...

Sheet 每日电表读数
B2: 08：00-08：00 | D2: 45658 | E2: 45659 | F2: 45660 | G2: 45661 | H2: 45662 | I2: 45663 | J2: 45664 | K2: 45665 | L2: 45666 | M2: 45667 | N2: 45668 | O2: 45669 | P2: 45670 | Q2: 45671 | R2: 45672 | S2: 45673 | T2: 45674 | U2: 45675 | V2: 45676 | W2: 45677 | X2: 45678 | Y2: 45679 | Z2: 45680 | AA2: 45681 | AB2: 45682 | AC2: 45683 | AD2: 45684 | AE2: 45685 | AF2: 45686 | AG2: 45687 | AH2: 45688 | AI2: 45689 | AJ2: 45690 | AK2: 45691 | AL2: 45692 | AM2: 45693 | AN2: 45694 | AO2: 45695 | AP2: 45696 | AQ2: 45697 | AR2: 45698 | AS2: 45699 | AT2: 45700 | AU2: 45701 | AV2: 45702 | AW2: 45703 | AX2: 45704 | AY2: 45705 | AZ2: 45706 | BA2: 45707 | BB2: 45708 | BC2: 45709 | BD2: 45710 | BE2: 45711 | BF2: 45712 | BG2: 45713 | BH2: 45714 | BI2: 45715 | BJ2: 45716 | BK2: 45717 | BL2: 45718 | BM2: 45719 | BN2: 45720 | BO2: 45721 | BP2: 45722 | BQ2: 45723 | BR2: 45724 | BS2: 45725 | BT2: 45726 | BU2: 45727 | BV2: 45728 | BW2: 45729 | BX2: 45730 | BY2: 45731 | BZ2: 45732 | CA2: 45733 | CB2: 45734 | CC2: 45735 | CD2: 45736 | CE2: 45737 | CF2: 45738 | CG2: 45739 | CH2: 45740 | CI2: 45741 | CJ2: 45742 | CK2: 45743 | CL2: 45744 | CM2: 45745 | CN2: 45746 | CO2: 45747 | CP2: 45748 | CQ2: 45749 | CR2: 45750 | CS2: 45751 | CT2: 45752 | CU2: 45753 | CV2: 45754 | CW2: 45755 | CX2: 45756 | CY2: 45757 | CZ2: 45758 | DA2: 45759 | DB2: 45760 | DC2: 45761 | DD2: 45762 | DE2: 45763 | DF2: 45764 | DG2: 45765 | DH2: 45766 | DI2: 45767 | DJ2: 45768 | DK2: 45769 | DL2: 45770 | DM2: 45771 | DN2: 45772 | DO2: 45773 | DP2: 45774 | DQ2: 45775 | DR2: 45776 | DS2: 45777 | DT2: 45778 | DU2: 45779 | DV2: 45780 | DW2: 45781 | DX2: 45782 | DY2: 45783 | DZ2: 45784 | EA2: 45785 | EB2: 45786 | EC2: 45787 | ED2: 45788 | EE2: 45789 | EF2: 45790 | EG2: 45791 | EH2: 45792 | EI2: 45793 | EJ2: 45794 | EK2: 45795 | EL2: 45796 | EM2: 45797 | EN2: 45798 | EO2: 45799 | EP2: 45800 | EQ2: 45801 | ER2: 45802 | ES2: 45803 | ET2: 45804 | EU2: 45805 | EV2: 45806 | EW2: 45807 | EX2: 45808 | EY2: 45809 | EZ2: 45810 | FA2: 45811 | FB2: 45812 | FC2: 45813 | FD2: 45814 | FE2: 45815 | FF2: 45816 | FG2: 45817 | FH2: 45818 | FI2: 45819 | FJ2: 45820 | FK2: 45821 | FL2: 45822 | FM2: 45823 | FN2: 45824 | FO2: 45825 | FP2: 45826 | FQ2: 45827 | FR2: 45828 | FS2: 45829 | FT2: 45830 | FU2: 45831 | FV2: 45832 | FW2: 45833 | FX2: 45834 | FY2: 45835 | FZ2: 45836 | GA2: 45837 | GB2: 45838 | GC2: 45839 | GD2: 45840 | GE2: 45841 | GF2: 45842 | GG2: 45843 | GH2: 45844 | GI2: 45845 | GJ2: 45846 | GK2: 45847 | GL2: 45848 | GM2: 45849 | GN2: 45850 | GO2: 45851 | GP2: 45852 | GQ2: 45853 | GR2: 45854 | GS2: 45855 | GT2: 45856 | GU2: 45857 | GV2: 45858 | GW2: 45859 | GX2: 45860 | GY2: 45861 | GZ2: 45862 | HA2: 45863 | HB2: 45864 | HC2: 45865 | HD2: 45866 | HE2: 45867 | HF2: 45868 | HG2: 45869 | HH2: 45870 | HI2: 45871 | HJ2: 45872 | HK2: 45873 | HL2: 45874 | HM2: 45875 | HN2: 45876 | HO2: 45877 | HP2: 45878 | HQ2: 45879 | HR2: 45880 | HS2: 45881 | HT2: 45882 | HU2: 45883 | HV2: 45884 | HW2: 45885 | HX2: 45886 | HY2: 45887 | HZ2: 45888 | IA2: 45889 | IB2: 45890 | IC2: 45891 | ID2: 45892 | IE2: 45893 | IF2: 45894 | IG2: 45895 | IH2: 45896 | II2: 45897 | IJ2: 45898 | IK2: 45899 | IL2: 45900 | IM2: 45901 | IN2: 45902 | IO2: 45903 | IP2: 45904 | IQ2: 45905 | IR2: 45906 | IS2: 45907 | IT2: 45908 | IU2: 45909 | IV2: 45910 | IW2: 45911 | IX2: 45912 | IY2: 45913 | IZ2: 45914 | JA2: 45915 | JB2: 45916 | JC2: 45917 | JD2: 45918 | JE2: 45919 | JF2: 45920 | JG2: 45921 | JH2: 45922 | JI2: 45923 | JJ2: 45924 | JK2: 45925 | JL2: 45926 | JM2: 45927 | JN2: 45928 | JO2: 45929 | JP2: 45930 | JQ2: 45931 | JR2: 45932 | JS2: 45933 | JT2: 45934 | JU2: 45935 | JV2: 45936 | JW2: 45937 | JX2: 45938 | JY2: 45939 | JZ2: 45940 | KA2: 45941 | KB2: 45942 | KC2: 45943 | KD2: 45944 | KE2: 45945 | KF2: 45946 | KG2: 45947 | KH2: 45948 | KI2: 45949 | KJ2: 45950 | KK2: 45951 | KL2: 45952 | KM2: 45953 | KN2: 45954 | KO2: 45955 | KP2: 45956 | KQ2: 45957 | KR2: 45958 | KS2: 45959 | KT2: 45960 | KU2: 45961 | KV2: 45962 | KW2: 45963 | KX2: 45964 | KY2: 45965 | KZ2: 45966 | LA2: 45967 | LB2: 45968 | LC2: 45969 | LD2: 45970 | LE2: 45971 | LF2: 45972 | LG2: 45973 | LH2: 45974 | LI2: 45975 | LJ2: 45976 | LK2: 45977 | LL2: 45978 | LM2: 45979 | LN2: 45980 | LO2: 45981 | LP2: 45982 | LQ2: 45983 | LR2: 45984 | LS2: 45985 | LT2: 45986 | LU2: 45987 | LV2: 45988 | LW2: 45989 | LX2: 45990 | LY2: 45991 | LZ2: 45992 | MA2: 45993 | MB2: 45994 | MC2: 45995 | MD2: 45996 | ME2: 45997 | MF2: 45998 | MG2: 45999 | MH2: 46000 | MI2: 46001 | MJ2: 46002 | MK2: 46003 | ML2: 46004 | MM2: 46005 | MN2: 46006 | MO2: 46007 | MP2: 46008 | MQ2: 46009 | MR2: 46010 | MS2: 46011 | MT2: 46012 | MU2: 46013 | MV2: 46014 | MW2: 46015 | MX2: 46016 | MY2: 46017 | MZ2: 46018 | NA2: 46019 | NB2: 46020 | NC2: 46021 | ND2: 46022 | NE2: 46023 | NF2: 46024 | NG2: 46025 | NH2: 46026 | NI2: 46027 | NJ2: 46028 | NK2: 46029 | NL2: 46030 | NM2: 46031 | NN2: 46032 | NO2: 46033 | NP2: 46034 | NQ2: 46035 | NR2: 46036 | NS2: 46037 | NT2: 46038 | NU2: 46039 | NV2: 46040 | NW2: 46041 | NX2: 46042 | NY2: 46043 | NZ2: 46044 | OA2: 46045 | OB2: 46046 | OC2: 46047 | OD2: 46048 | OE2: 46049 | OF2: 46050 | OG2: 46051 | OH2: 46052 | OI2: 46053 | OJ2: 46054 | OK2: 46055 | OL2: 46056 | OM2: 46057 | ON2: 46058 | OO2: 46059 | OP2: 46060 | OQ2: 46061 | OR2: 46062 | OS2: 46063 | OT2: 46064 | OU2: 46065 | OV2: 46066 | OW2: 46067 | OX2: 46068 | OY2: 46069 | OZ2: 46070 | PA2: 46071 | PB2: 46072 | PC2: 46073 | PD2: 46074 | PE2: 46075 | PF2: 46076 | PG2: 46077 | PH2: 46078 | PI2: 46079 | PJ2: 46080 | PK2: 46081 | PL2: 46082 | PM2: 46083 | PN2: 46084 | PO2: 46085 | PP2: 46086 | PQ2: 46087 | PR2: 46088 | PS2: 46089 | PT2: 46090 | PU2: 46091 | PV2: 46092 | PW2: 46093 | PX2: 46094 | PY2: 46095 | PZ2: 46096 | QA2: 46097 | QB2: 46098 | QC2: 46099 | QD2: 46100 | QE2: 46101 | QF2: 46102 | QG2: 46103 | QH2: 46104 | QI2: 46105 | QJ2: 46106 | QK2: 46107 | QL2: 46108 | QM2: 46109 | QN2: 46110 | QO2: 46111 | QP2: 46112 | QQ2: 46113 | QR2: 46114 | QS2: 46115 | QT2: 46116 | QU2: 46117 | QV2: 46118 | QW2: 46119 | QX2: 46120 | QY2: 46121 | QZ2: 46122 | RA2: 46123 | RB2: 46124 | RC2: 46125 | RD2: 46126 | RE2: 46127 | RF2: 46128 | RG2: 46129 | RH2: 46130 | RI2: 46131 | RJ2: 46132 | RK2: 46133 | RL2: 46134 | RM2: 46135 | RN2: 46136 | RO2: 46137 | RP2: 46138 | RQ2: 46139 | RR2: 46140 | RS2: 46141 | RT2: 46142 | RU2: 46143 | RV2: 46144 | RW2: 46145 | RX2: 46146 | RY2: 46147 | RZ2: 46148 | SA2: 46149 | SB2: 46150 | SC2: 46151 | SD2: 46152 | SE2: 46153 | SF2: 46154 | SG2: 46155 | SH2: 46156 | SI2: 46157 | SJ2: 46158 | SK2: 46159 | SL2: 46160 | SM2: 46161 | SN2: 46162 | SO2: 46163 | SP2: 46164 | SQ2: 46165 | SR2: 46166 | SS2: 46167 | ST2: 46168 | SU2: 46169 | SV2: 46170 | SW2: 46171 | SX2: 46172 | SY2: 46173 | SZ2: 46174 | TA2: 46175 | TB2: 46176 | TC2: 46177 | TD2: 46178 | TE2: 46179 | TF2: 46180 | TG2: 46181 | TH2: 46182 | TI2: 46183 | TJ2: 46184 | TK2: 46185 | TL2: 46186 | TM2: 46187 | TN2: 46188 | TO2: 46189
A3: F1-1F照明插座 (ổ cắm, chiếu sáng) | C3: F1L11 | D3: 212683.3 | E3: 212707.8 | F3: 212923.7 | G3: 213139.3 | H3: 213312.2 | I3: 213339.2 | J3: 213550.9 | K3: 213763.2 | L3: 213993.6 | M3: 214212.9 | N3: 214390.4 | O3: 214583 | P3: 214735.2 | Q3: 214967.5 | R3: 215213.8 | S3: 215473.6 | T3: 215738.8 | U3: 215971.9 | V3: 216186.7 | W3: 216220.3 | X3: 216469.3 | Y3: 216720.6 | Z3: 216974.8 | AA3: 217179.6 | AB3: 217402.6 | AC3: 217574.6 | AD3: 217607.4 | AE3: 217685.5 | AF3: 217702.1 | AG3: 217718.7 | AH3: 217739.9 | AI3: 217771.4 | AJ3: 217843.9 | AK3: 217875.9 | AL3: 218095.9 | AM3: 218313.7 | AN3: 218524.3 | AO3: 218744.3 | AP3: 218919.2 | AQ3: 219082.7 | AR3: 219113.3 | AS3: 219327.8 | AT3: 219540.8 | AU3: 219762.8 | AV3: 219984.4 | AW3: 220186.1 | AX3: 220354.8 | AY3: 220450.7 | AZ3: 220670 | BA3: 220889.2 | BB3: 221101.4 | BC3: 221326.2 | BD3: 221498.4 | BE3: 221663.7 | BF3: 221718.3 | BG3: 221936.7 | BH3: 222152.5 | BI3: 222370.1 | BJ3: 222589 | BK3: 222761.1 | BL3: 222925.2 | BM3: 222958.8 | BN3: 223184.7 | BO3: 223353.5 | BP3: 223527.8 | BQ3: 223698.8 | BR3: 223863 | BS3: 224025.8 | BT3: 224062.9 | BU3: 224235.3 | BV3: 224403.6 | BW3: 224578.6 | BX3: 224777.6 | BY3: 224946.6 | BZ3: 225132.7 | CA3: 225170.3 | CB3: 225342.8 | CC3: 225538.6 | CD3: 225741.8 | CE3: 225944 | CF3: 226161.6 | CG3: 226325.2 | CH3: 226362.1 | CI3: 226592 | CJ3: 226812.2 | CK3: 227028.4 | CL3: 227248.9 | CM3: 227439.7 | CN3: 227606.8 | CO3: 227643.1 | CP3: 227864.7 | CQ3: 228081.2 | CR3: 228305.9 | CS3: 228520.3 | CT3: 228706.7 | CU3: 228779.3 | CV3: 228790.2 | CW3: 228805.4 | CX3: 228902.1 | CY3: 229020.7 | CZ3: 229182.6 | DA3: 229278.2 | DB3: 229359.7 | DC3: 229374.2 | DD3: 229504.9 | DE3: 229656 | DF3: 229769.2 | DG3: 229884.3 | DH3: 229982 | DI3: 230079.4 | DJ3: 230091.3 | DK3: 230243.1 | DL3: 230391.8 | DM3: 230501.4 | DN3: 230620.4 | DO3: 230746 | DP3: 230855 | DQ3: 230888.1 | DR3: 231034.3 | DS3: 231143.9 | DT3: 231208.3 | DU3: 231219.2 | DV3: 231345.2 | DW3: 231468.2 | DX3: 231567.4 | DY3: 231693.9 | DZ3: 231858.8 | EA3: 232011.8 | EB3: 232044.8 | EC3: 232196.7 | ED3: 232298.9 | EE3: 232389.8 | EF3: 232530.9 | EG3: 232661.6 | EH3: 232799.8 | EI3: 232941 | EJ3: 233089.6 | EK3: 233211.4 | EL3: 233273.3 | EM3: 233392.2 | EN3: 233517.1 | EO3: 233642.2 | EP3: 233768 | EQ3: 233927.8 | ER3: 234073.1 | ES3: 234089.5 | ET3: 234233.3 | EU3: 234378.4 | EV3: 234524.7 | EW3: 234684.1 | EX3: 234833.8 | EY3: 234992.7 | EZ3: 235119.2 | FA3: 235264.2 | FB3: 235410.1 | FC3: 235564.9 | FD3: 235757.3 | FE3: 235907.8 | FF3: 236024.6 | FG3: 236143.5 | FH3: 236297.7 | FI3: 236443.7 | FJ3: 236603.9 | FK3: 236758 | FL3: 236923.6 | FM3: 237072.2 | FN3: 237086.2 | FO3: 237224.3 | FP3: 237414.5 | FQ3: 237622.4 | FR3: 237838.2 | FS3: 238048.6 | FT3: 238258.1 | FU3: 238273.3 | FV3: 238403 | FW3: 238538.8 | FX3: 238690.2 | FY3: 238861.6 | FZ3: 239027.8 | GA3: 239156.3 | GB3: 239180.7 | GC3: 239331 | GD3: 239465.1 | GE3: 239600.2 | GF3: 239736.3 | GG3: 239852.8 | GH3: 239973.5 | GI3: 239994.3 | GJ3: 240135.2 | GK3: 240278.5 | GL3: 240443.7 | GM3: 240602 | GN3: 240754.3 | GO3: 240913.2 | GP3: 240928.4 | GQ3: 241075.6 | GR3: 241231.7 | GS3: 241326.7 | GT3: 241410.2 | GU3: 241546.9 | GV3: 241626.5 | GW3: 241640.6 | GX3: 241741.7 | GY3: 241759.4 | GZ3: 241866 | HA3: 241980.6 | HB3: 242084.2 | HC3: 242175.2 | HD3: 242185.6 | HE3: 242277 | HF3: 242386 | HG3: 242507.7 | HH3: 242637.8 | HI3: 242729 | HJ3: 242818.8 | HK3: 242826 | HL3: 242931.9 | HM3: 243039.4 | HN3: 243163.3 | HO3: 243263.2 | HP3: 243346.2 | HQ3: 243422.1 | HR3: 243434.5 | HS3: 243553.3 | HT3: 243670.1 | HU3: 243770 | HV3: 243857.1 | HW3: 243935.8 | HX3: 244027 | HY3: 244036.3 | HZ3: 244138.5 | IA3: 244208.9 | IB3: 244297.4 | IC3: 244381.9 | ID3: 244461.2 | IE3: 244537.6 | IF3: 244547.2 | IG3: 244647.4 | IH3: 244740.1 | II3: 244874.7 | IJ3: 244994.7 | IK3: 245130.2 | IL3: 245216 | IM3: 245232.2 | IN3: 245238.1 | IO3: 245245.6 | IP3: 245348.5 | IQ3: 245443.2 | IR3: 245536.2 | IS3: 245620.5 | IT3: 245631.3 | IU3: 245719 | IV3: 245802.7 | IW3: 245902.7 | IX3: 246000.4 | IY3: 246100.1 | IZ3: 246192.5 | JA3: 246206 | JB3: 246305.5 | JC3: 246400.1 | JD3: 246481.9 | JE3: 246570.3 | JF3: 246668.5 | JG3: 246761.8 | JH3: 246771.6 | JI3: 246860.6 | JJ3: 246957.7 | JK3: 247066.8 | JL3: 247158.8 | JM3: 247252.7 | JN3: 247323.2 | JO3: 247340.9 | JP3: 247432.7 | JQ3: 247522 | JR3: 247599.3 | JS3: 247692.4 | JT3: 247789.9 | JU3: 247868.8 | JV3: 247878.3 | JW3: 247966.3 | JX3: 248074.3 | JY3: 248190.9 | JZ3: 248323.2 | KA3: 248450 | KB3: 248573.4 | KC3: 248588.7 | KD3: 248735 | KE3: 248871.8 | KF3: 249002.9 | KG3: 249169.4 | KH3: 249284.9 | KI3: 249401 | KJ3: 249411.6 | KK3: 249580.6 | KL3: 249707.2 | KM3: 249803.7 | KN3: 249904.1 | KO3: 250008.2 | KP3: 250109.4 | KQ3: 250126.8 | KR3: 250257.5 | KS3: 250376.7 | KT3: 250513 | KU3: 250628.9 | KV3: 250729 | KW3: 250823.9 | KX3: 250844 | KY3: 250990.7 | KZ3: 251119.4 | LA3: 251254.9 | LB3: 251377.1 | LC3: 251462.3 | LD3: 251555.9 | LE3: 251575.5 | LF3: 251672.5 | LG3: 251778.8 | LH3: 251886.7 | LI3: 251982.1 | LJ3: 252105.4 | LK3: 252206.8 | LL3: 252235.7 | LM3: 252339.7 | LN3: 252449.7 | LO3: 252598.4 | LP3: 252728.9 | LQ3: 252840 | LR3: 252955.9 | LS3: 252986.9 | LT3: 253128.1 | LU3: 253227.6 | LV3: 253327 | LW3: 253429.9 | LX3: 253512.8 | LY3: 253557.3 | LZ3: 253579.2 | MA3: 253647.4 | MB3: 253740 | MC3: 253829.4 | MD3: 253904.4 | ME3: 253973.3 | MF3: 254023.4 | MG3: 254047.7 | MH3: 254155.8 | MI3: 254262.5 | MJ3: 254409.6 | MK3: 254540.1 | ML3: 254633.8 | MM3: 254706.5 | MN3: 254733.7 | MO3: 254816.2 | MP3: 254909.6 | MQ3: 255002 | MR3: 255116.5 | MS3: 255204.3 | MT3: 255264.9 | MU3: 255277.6 | MV3: 255361.6 | MW3: 255457.6 | MX3: 255558.3 | MY3: 255653 | MZ3: 255743 | NA3: 255792.3 | NB3: 255814.1 | NC3: 255887 | ND3: 256016.3 | NE3: 256074.7 | NF3: 256101.1 | NG3: 256210.7 | NH3: 256300.2 | NI3: 256328.6 | NJ3: 256440 | NK3: 256551.7 | NL3: 256652.8 | NM3: 256761.1 | NN3: 256865.5 | NO3: 256887.1 | NP3: 256912.2 | NQ3: 256997.9 | NR3: 257101.6 | NS3: 257214.3 | NT3: 257318.2 | NU3: 257410.2 | NV3: 257499 | NW3: 257524.1 | NX3: 257612.2 | NY3: 257641.4 | NZ3: 257731.4 | OA3: 257772.1 | OB3: 257801.7 | OC3: 257820.3 | OD3: 257831.3 | OE3: 257871.8 | OF3: 257912.2 | OG3: 257961.2 | OH3: 258010.2 | OI3: 258081.1 | OJ3: 258172.2 | OK3: 258200.2 | OL3: 258312.5 | OM3: 258365.2 | ON3: 258422.6 | OO3: 258482.2 | OP3: 258531.2 | OQ3: 258563.2 | OR3: 258591 | OS3: 258686.8 | OT3: 258811.6 | OU3: 258925 | OV3: 259020.9 | OW3: 259118.7 | OX3: 259149.2 | OY3: 259155.3 | OZ3: 259161.7 | PA3: 259171.2 | PB3: 259187.6 | PC3: 259203.8 | PD3: 259220.8 | PE3: 259240.3 | PF3: 259258.9 | PG3: 259358.4 | PH3: 259459.7 | PI3: 259566.5 | PJ3: 259681.8 | PK3: 259777.1 | PL3: 259872.8 | PM3: 259903.7 | PN3: 260018.6 | PO3: 260165.4 | PP3: 260316.1 | PQ3: 260459.4 | PR3: 260560.3 | PS3: 260689.3 | PT3: 260713 | PU3: 260828.4 | PV3: 260965.2 | PW3: 261103.4 | PX3: 261250.3 | PY3: 261379.2 | PZ3: 261472.4 | QA3: 261499.4 | QB3: 261644.4 | QC3: 261781 | QD3: 261902.2 | QE3: 262028.3 | QF3: 262141.4 | QG3: 262285.7 | QH3: 262445.6 | QI3: 262581.9 | QJ3: 262735.7 | QK3: 262906.7 | QL3: 263070.5 | QM3: 263203.7 | QN3: 263310.2 | QO3: 263337.9 | QP3: 263483.5 | QQ3: 263606.3 | QR3: 263797.5 | QS3: 263926.7 | QT3: 264076.2 | QU3: 264105.4 | QV3: 264141.1 | QW3: 264280.6 | QX3: 264403.2 | QY3: 264544.1 | QZ3: 264682 | RA3: 264829.3 | RB3: 264947.9 | RC3: 264980.8 | RD3: 265119.4 | RE3: 265250.6 | RF3: 265386.2 | RG3: 265525.1 | RH3: 265644 | RI3: 265666.2 | RJ3: 265693.6 | RK3: 265811.5 | RL3: 265931.4 | RM3: 266070.1 | RN3: 266228.2 | RO3: 266346.9 | RP3: 266438.7 | RQ3: 266466.4 | RR3: 266494.9 | RS3: 266606.5 | RT3: 266705.4 | RU3: 266719.8 | RV3: 266734 | RW3: 266750.9 | RX3: 266773.8 | RY3: 266900.8 | RZ3: 267023.1 | SA3: 267163.9 | SB3: 267291.4 | SC3: 267414.2 | SD3: 267525.4 | SE3: 267671.2 | SF3: 267824 | SG3: 267966.4 | SH3: 268112.3 | SI3: 268238.1 | SJ3: 268344.5 | SK3: 268472.9 | SL3: 268505.1 | SM3: 268629.3 | SN3: 268755 | SO3: 268907.6 | SP3: 269040.6 | SQ3: 269185.5 | SR3: 269323.3 | SS3: 269355.2 | ST3: 269484.2 | SU3: 269630.6 | SV3: 269771.3 | SW3: 269917.8 | SX3: 270026.6 | SY3: 270052.3 | SZ3: 270076.7 | TA3: 270205.8 | TB3: 270349.7 | TC3: 270475.2 | TD3: 270607.3 | TE3: 270756.3 | TF3: 270910.4 | TG3: 270937.4 | TH3: 271060.5 | TI3: 271193.2 | TJ3: 271345.4 | TK3: 271504.5 | TL3: 271659.5 | TM3: 271808.5 | TN3: 271835.9 | TO3: 271997.2
C4: F1L12 | D4: 109219.3 | E4: 109326.4 | F4: 109435.5 | G4: 109561.3 | H4: 109652.7 | I4: 109691.3 | J4: 109800 | K4: 109920.9 | L4: 110031.9 | M4: 110181 | N4: 110299.2 | O4: 110396.4 | P4: 110484.2 | Q4: 110604.5 | R4: 110746.4 | S4: 110903.2 | T4: 111026.1 | U4: 111128.9 | V4: 111239 | W4: 111279 | X4: 111385.6 | Y4: 111531 | Z4: 111667.3 | AA4: 111799.4 | AB4: 111910.6 | AC4: 112015.5 | AD4: 112049.5 | AE4: 112111.5 | AF4: 112137.6 | AG4: 112164.1 | AH4: 112190.1 | AI4: 112218.3 | AJ4: 112247.1 | AK4: 112284.1 | AL4: 112425.2 | AM4: 112555.2 | AN4: 112679 | AO4: 112799.8 | AP4: 112903.2 | AQ4: 113007.6 | AR4: 113063.8 | AS4: 113202 | AT4: 113350.9 | AU4: 113482.5 | AV4: 113608.3 | AW4: 113712.6 | AX4: 113817.3 | AY4: 113855.7 | AZ4: 113997 | BA4: 114120.8 | BB4: 114289.4 | BC4: 114422.5 | BD4: 114526.7 | BE4: 114640 | BF4: 114686.9 | BG4: 114822.8 | BH4: 114966.5 | BI4: 115091.8 | BJ4: 115228.4 | BK4: 115338.5 | BL4: 115441.3 | BM4: 115480 | BN4: 115652 | BO4: 115761 | BP4: 115895.8 | BQ4: 116009.9 | BR4: 116125.7 | BS4: 116240.3 | BT4: 116278.9 | BU4: 116398.9 | BV4: 116514.1 | BW4: 116639.4 | BX4: 116751.7 | BY4: 116860.3 | BZ4: 116986.5 | CA4: 117035.3 | CB4: 117146.4 | CC4: 117258.7 | CD4: 117393.1 | CE4: 117532.9 | CF4: 117670.2 | CG4: 117783 | CH4: 117811.8 | CI4: 117956.1 | CJ4: 118110.1 | CK4: 118259.5 | CL4: 118406.4 | CM4: 118530.6 | CN4: 118630.4 | CO4: 118653.7 | CP4: 118793.7 | CQ4: 118937.1 | CR4: 119071.7 | CS4: 119179.1 | CT4: 119280.9 | CU4: 119349.5 | CV4: 119372.7 | CW4: 119398.9 | CX4: 119485 | CY4: 119583.7 | CZ4: 119688.5 | DA4: 119763.6 | DB4: 119835.4 | DC4: 119859.7 | DD4: 119973.2 | DE4: 120075.3 | DF4: 120182.3 | DG4: 120269.1 | DH4: 120348.5 | DI4: 120414 | DJ4: 120436.9 | DK4: 120550.4 | DL4: 120671.5 | DM4: 120759 | DN4: 120840.4 | DO4: 120909.9 | DP4: 120977.3 | DQ4: 121013.7 | DR4: 121118.6 | DS4: 121201.6 | DT4: 121258.3 | DU4: 121280.7 | DV4: 121386.2 | DW4: 121491 | DX4: 121564.1 | DY4: 121671.9 | DZ4: 121776.6 | EA4: 121892.9 | EB4: 121933.3 | EC4: 122047 | ED4: 122140 | EE4: 122220 | EF4: 122341.4 | EG4: 122460.8 | EH4: 122575.7 | EI4: 122705.9 | EJ4: 122816.9 | EK4: 122931 | EL4: 123035.3 | EM4: 123155.3 | EN4: 123275.1 | EO4: 123390.5 | EP4: 123503.6 | EQ4: 123627.5 | ER4: 123735.1 | ES4: 123749 | ET4: 123881.1 | EU4: 124014.6 | EV4: 124169 | EW4: 124324.7 | EX4: 124492.1 | EY4: 124647.2 | EZ4: 124796.6 | FA4: 124959.8 | FB4: 125095 | FC4: 125252.2 | FD4: 125410.5 | FE4: 125570.7 | FF4: 125703.1 | FG4: 125799.5 | FH4: 125972.6 | FI4: 126135.2 | FJ4: 126329.7 | FK4: 126489.7 | FL4: 126638 | FM4: 126794.4 | FN4: 126821.4 | FO4: 127021.8 | FP4: 127180.1 | FQ4: 127368 | FR4: 127569.5 | FS4: 127730.2 | FT4: 127900.8 | FU4: 127976.9 | FV4: 128134.9 | FW4: 128290.8 | FX4: 128486.8 | FY4: 128667.3 | FZ4: 128850.3 | GA4: 129034.7 | GB4: 129072.3 | GC4: 129240.4 | GD4: 129429.8 | GE4: 129573.9 | GF4: 129713 | GG4: 129847.4 | GH4: 129988 | GI4: 130061 | GJ4: 130210.9 | GK4: 130368.2 | GL4: 130543.6 | GM4: 130674.5 | GN4: 130817.9 | GO4: 130945.4 | GP4: 130987.6 | GQ4: 131109.9 | GR4: 131216.9 | GS4: 131341.6 | GT4: 131465.9 | GU4: 131581.3 | GV4: 131706 | GW4: 131772.2 | GX4: 131872.6 | GY4: 131917 | GZ4: 132043.7 | HA4: 132158.6 | HB4: 132269.4 | HC4: 132370.7 | HD4: 132404.7 | HE4: 132502.3 | HF4: 132617.3 | HG4: 132752.4 | HH4: 132859.2 | HI4: 132948.2 | HJ4: 133029.6 | HK4: 133055.8 | HL4: 133175.8 | HM4: 133299.3 | HN4: 133405.7 | HO4: 133495.1 | HP4: 133580.2 | HQ4: 133657.2 | HR4: 133689.2 | HS4: 133804.4 | HT4: 133906.8 | HU4: 134029.6 | HV4: 134120.5 | HW4: 134222.8 | HX4: 134319 | HY4: 134343.3 | HZ4: 134432.5 | IA4: 134520.4 | IB4: 134615.5 | IC4: 134718.8 | ID4: 134812.1 | IE4: 134902.3 | IF4: 134924.8 | IG4: 135032.8 | IH4: 135137.8 | II4: 135233.4 | IJ4: 135313.5 | IK4: 135419.1 | IL4: 135501.1 | IM4: 135545.5 | IN4: 135586.9 | IO4: 135610.7 | IP4: 135722 | IQ4: 135825.4 | IR4: 135930.2 | IS4: 136016.5 | IT4: 136054 | IU4: 136136.2 | IV4: 136237 | IW4: 136323.5 | IX4: 136418.3 | IY4: 136521.7 | IZ4: 136608.5 | JA4: 136648.7 | JB4: 136747.5 | JC4: 136844.3 | JD4: 136930.7 | JE4: 137008.3 | JF4: 137095.3 | JG4: 137183.3 | JH4: 137221.4 | JI4: 137305.7 | JJ4: 137397.6 | JK4: 137482.3 | JL4: 137568.5 | JM4: 137663 | JN4: 137739.3 | JO4: 137786.9 | JP4: 137879.1 | JQ4: 137973.6 | JR4: 138069 | JS4: 138166.7 | JT4: 138257.5 | JU4: 138332.2 | JV4: 138364.3 | JW4: 138448.9 | JX4: 138532.5 | JY4: 138627.1 | JZ4: 138733.2 | KA4: 138846.1 | KB4: 138947.1 | KC4: 138983.2 | KD4: 139093.9 | KE4: 139192.4 | KF4: 139294 | KG4: 139406.2 | KH4: 139495.1 | KI4: 139580.4 | KJ4: 139610.6 | KK4: 139726.8 | KL4: 139806.9 | KM4: 139862.4 | KN4: 139932.8 | KO4: 140018 | KP4: 140091.2 | KQ4: 140114.8 | KR4: 140184.2 | KS4: 140253.8 | KT4: 140348.2 | KU4: 140434.3 | KV4: 140499.1 | KW4: 140576.6 | KX4: 140604.6 | KY4: 140691.6 | KZ4: 140782.7 | LA4: 140873.5 | LB4: 140951.3 | LC4: 141000.5 | LD4: 141080.9 | LE4: 141094.3 | LF4: 141178.3 | LG4: 141267.9 | LH4: 141354.7 | LI4: 141428.5 | LJ4: 141503 | LK4: 141579.7 | LL4: 141604.6 | LM4: 141703 | LN4: 141784.4 | LO4: 141862.2 | LP4: 141941.9 | LQ4: 141983.2 | LR4: 142036.8 | LS4: 142060.3 | LT4: 142154.6 | LU4: 142214.4 | LV4: 142267.6 | LW4: 142322.6 | LX4: 142397.9 | LY4: 142439.6 | LZ4: 142459.6 | MA4: 142501.9 | MB4: 142548.6 | MC4: 142602.2 | MD4: 142659.8 | ME4: 142719.2 | MF4: 142774.4 | MG4: 142799.8 | MH4: 142864.2 | MI4: 142929.3 | MJ4: 143002 | MK4: 143078.6 | ML4: 143143.2 | MM4: 143214.2 | MN4: 143231.3 | MO4: 143313.2 | MP4: 143393.3 | MQ4: 143454.3 | MR4: 143528.7 | MS4: 143589 | MT4: 143656.4 | MU4: 143679.9 | MV4: 143762.2 | MW4: 143841.9 | MX4: 143923.1 | MY4: 143999.2 | MZ4: 144065.2 | NA4: 144110.7 | NB4: 144131.7 | NC4: 144210.7 | ND4: 144275 | NE4: 144326.5 | NF4: 144376.1 | NG4: 144445.6 | NH4: 144526.1 | NI4: 144551.8 | NJ4: 144646.8 | NK4: 144725.9 | NL4: 144786.8 | NM4: 144870.6 | NN4: 144952.2 | NO4: 144996.6 | NP4: 145020 | NQ4: 145116 | NR4: 145192 | NS4: 145266.1 | NT4: 145338.2 | NU4: 145398.6 | NV4: 145466.8 | NW4: 145487.7 | NX4: 145537.1 | NY4: 145648.6 | NZ4: 145709 | OA4: 145739.3 | OB4: 145766.1 | OC4: 145787.6 | OD4: 145809.1 | OE4: 145845.5 | OF4: 145881.1 | OG4: 145913.9 | OH4: 145949 | OI4: 145981.1 | OJ4: 146012.9 | OK4: 146028.8 | OL4: 146078.9 | OM4: 146123.4 | ON4: 146179.1 | OO4: 146234.2 | OP4: 146271.5 | OQ4: 146307.9 | OR4: 146337 | OS4: 146377 | OT4: 146444.7 | OU4: 146507 | OV4: 146574.7 | OW4: 146642.4 | OX4: 146666.8 | OY4: 146683.6 | OZ4: 146700.9 | PA4: 146720.8 | PB4: 146737.4 | PC4: 146754 | PD4: 146770.9 | PE4: 146788.7 | PF4: 146806.7 | PG4: 146855.9 | PH4: 146933.4 | PI4: 147009.9 | PJ4: 147088.7 | PK4: 147126.1 | PL4: 147156.9 | PM4: 147191.6 | PN4: 147271 | PO4: 147350 | PP4: 147428.5 | PQ4: 147505 | PR4: 147570.4 | PS4: 147650.5 | PT4: 147671.1 | PU4: 147756 | PV4: 147830.9 | PW4: 147914.3 | PX4: 147998.7 | PY4: 148090.1 | PZ4: 148163.5 | QA4: 148203.5 | QB4: 148295.4 | QC4: 148396.8 | QD4: 148463.7 | QE4: 148535.9 | QF4: 148605.3 | QG4: 148671.8 | QH4: 148713.2 | QI4: 148795.5 | QJ4: 148887.5 | QK4: 149001.6 | QL4: 149117.1 | QM4: 149214.2 | QN4: 149250.9 | QO4: 149272.1 | QP4: 149342.2 | QQ4: 149416.4 | QR4: 149506.9 | QS4: 149597.8 | QT4: 149701.4 | QU4: 149739.2 | QV4: 149761.4 | QW4: 149845.2 | QX4: 149970.3 | QY4: 150058.4 | QZ4: 150127.9 | RA4: 150195.8 | RB4: 150264.9 | RC4: 150293.1 | RD4: 150384.4 | RE4: 150495.3 | RF4: 150581.6 | RG4: 150669.7 | RH4: 150759.8 | RI4: 150799.5 | RJ4: 150831.6 | RK4: 150920.6 | RL4: 150998.3 | RM4: 151105.6 | RN4: 151220.8 | RO4: 151321.1 | RP4: 151374 | RQ4: 151397.4 | RR4: 151423.2 | RS4: 151483.7 | RT4: 151544.8 | RU4: 151564.2 | RV4: 151587.2 | RW4: 151612.4 | RX4: 151638.1 | RY4: 151713.7 | RZ4: 151827 | SA4: 151931 | SB4: 152036 | SC4: 152122.5 | SD4: 152192.9 | SE4: 152300.3 | SF4: 152414.2 | SG4: 152542.8 | SH4: 152649.7 | SI4: 152772.7 | SJ4: 152868.5 | SK4: 152991.4 | SL4: 153020.3 | SM4: 153144.1 | SN4: 153281.5 | SO4: 153398.2 | SP4: 153513.3 | SQ4: 153608.1 | SR4: 153715.1 | SS4: 153767 | ST4: 153895.6 | SU4: 154018.4 | SV4: 154141.9 | SW4: 154253.2 | SX4: 154351.6 | SY4: 154412 | SZ4: 154449.2 | TA4: 154572.4 | TB4: 154704 | TC4: 154838.7 | TD4: 154945.1 | TE4: 155083.8 | TF4: 155213.2 | TG4: 155249.6 | TH4: 155395 | TI4: 155520.6 | TJ4: 155644.5 | TK4: 155753.8 | TL4: 155875.6 | TM4: 155973.4 | TN4: 156003 | TO4: 156136.6
C5: F1EL11 | D5: 59768.1 | E5: 59780.3 | F5: 59835 | G5: 59888.6 | H5: 59928.9 | I5: 59941.1 | J5: 59992.1 | K5: 60045.3 | L5: 60104.1 | M5: 60158.5 | N5: 60200.5 | O5: 60251.5 | P5: 60293.6 | Q5: 60352.8 | R5: 60407.1 | S5: 60460.9 | T5: 60515.5 | U5: 60557.4 | V5: 60600.9 | W5: 60612.9 | X5: 60666.4 | Y5: 60720.9 | Z5: 60774.9 | AA5: 60818.5 | AB5: 60865.1 | AC5: 60907.1 | AD5: 60918 | AE5: 60939.6 | AF5: 60950.2 | AG5: 60960.8 | AH5: 60971.4 | AI5: 60982.1 | AJ5: 60998 | AK5: 61009.9 | AL5: 61061.4 | AM5: 61113 | AN5: 61164.1 | AO5: 61218.3 | AP5: 61261.1 | AQ5: 61302.2 | AR5: 61313.7 | AS5: 61367.9 | AT5: 61422.8 | AU5: 61477.8 | AV5: 61532.3 | AW5: 61576.7 | AX5: 61618.7 | AY5: 61663.3 | AZ5: 61715.7 | BA5: 61770.2 | BB5: 61823.4 | BC5: 61878.3 | BD5: 61922.2 | BE5: 61964.8 | BF5: 61985 | BG5: 62040.6 | BH5: 62094.9 | BI5: 62149.8 | BJ5: 62205.9 | BK5: 62251.3 | BL5: 62294.7 | BM5: 62308 | BN5: 62364.9 | BO5: 62410.6 | BP5: 62456.7 | BQ5: 62502.7 | BR5: 62548.3 | BS5: 62589 | BT5: 62602.2 | BU5: 62645.5 | BV5: 62687.6 | BW5: 62729.4 | BX5: 62779.4 | BY5: 62821 | BZ5: 62874.8 | CA5: 62890.2 | CB5: 62934.6 | CC5: 62980.6 | CD5: 63030.2 | CE5: 63079.8 | CF5: 63129.8 | CG5: 63168.8 | CH5: 63180.5 | CI5: 63226.6 | CJ5: 63273.7 | CK5: 63321.1 | CL5: 63368.3 | CM5: 63407.4 | CN5: 63444 | CO5: 63456 | CP5: 63503.6 | CQ5: 63551.9 | CR5: 63600.5 | CS5: 63646.6 | CT5: 63692.4 | CU5: 63707.6 | CV5: 63719.3 | CW5: 63731 | CX5: 63742.3 | CY5: 63754 | CZ5: 63790.5 | DA5: 63802.3 | DB5: 63817 | DC5: 63829 | DD5: 63840.9 | DE5: 63853.1 | DF5: 63879.5 | DG5: 63893 | DH5: 63910.7 | DI5: 63928 | DJ5: 63939.4 | DK5: 63979.2 | DL5: 63990 | DM5: 64002.1 | DN5: 64021.6 | DO5: 64061.6 | DP5: 64069.5 | DQ5: 64078 | DR5: 64116.3 | DS5: 64138.8 | DT5: 64149.8 | DU5: 64160.8 | DV5: 64200.9 | DW5: 64243 | DX5: 64274 | DY5: 64301.6 | DZ5: 64342.4 | EA5: 64378.6 | EB5: 64393.6 | EC5: 64438.4 | ED5: 64473.9 | EE5: 64509.1 | EF5: 64550.9 | EG5: 64593.5 | EH5: 64638.2 | EI5: 64680.3 | EJ5: 64720.6 | EK5: 64751.1 | EL5: 64761.4 | EM5: 64777.8 | EN5: 64800.7 | EO5: 64820.8 | EP5: 64844.6 | EQ5: 64855.3 | ER5: 64897.6 | ES5: 64902.5 | ET5: 64944 | EU5: 64988.9 | EV5: 65031.4 | EW5: 65075 | EX5: 65122.2 | EY5: 65166.2 | EZ5: 65202.5 | FA5: 65240.9 | FB5: 65283.1 | FC5: 65324.9 | FD5: 65366.8 | FE5: 65411.7 | FF5: 65449.4 | FG5: 65476.9 | FH5: 65522.9 | FI5: 65569.5 | FJ5: 65612.8 | FK5: 65645.9 | FL5: 65671.5 | FM5: 65715 | FN5: 65726.4 | FO5: 65775.1 | FP5: 65830.1 | FQ5: 65871.3 | FR5: 65912 | FS5: 65978.4 | FT5: 66048 | FU5: 66058.9 | FV5: 66105 | FW5: 66151.1 | FX5: 66199.6 | FY5: 66245.4 | FZ5: 66287.5 | GA5: 66327.9 | GB5: 66338.6 | GC5: 66389.7 | GD5: 66434.8 | GE5: 66480.8 | GF5: 66524.7 | GG5: 66568.7 | GH5: 66598 | GI5: 66607.6 | GJ5: 66631.2 | GK5: 66657.8 | GL5: 66696.2 | GM5: 66740.3 | GN5: 66784.2 | GO5: 66831.4 | GP5: 66850.5 | GQ5: 66900.1 | GR5: 66941.3 | GS5: 66960.3 | GT5: 66976.2 | GU5: 66999.9 | GV5: 67025.9 | GW5: 67034.9 | GX5: 67049.8 | GY5: 67062 | GZ5: 67095.4 | HA5: 67116.3 | HB5: 67128 | HC5: 67138.8 | HD5: 67147.6 | HE5: 67161 | HF5: 67187.1 | HG5: 67195.3 | HH5: 67207.2 | HI5: 67232.7 | HJ5: 67259.4 | HK5: 67269.4 | HL5: 67282.3 | HM5: 67295 | HN5: 67304.9 | HO5: 67329.8 | HP5: 67351.2 | HQ5: 67364.5 | HR5: 67373.9 | HS5: 67389.7 | HT5: 67399.8 | HU5: 67415.3 | HV5: 67424.1 | HW5: 67434.1 | HX5: 67452.1 | HY5: 67461.8 | HZ5: 67485.2 | IA5: 67502.7 | IB5: 67518.1 | IC5: 67536.6 | ID5: 67556.4 | IE5: 67572.7 | IF5: 67581.1 | IG5: 67596.8 | IH5: 67613.8 | II5: 67634.5 | IJ5: 67659.8 | IK5: 67688 | IL5: 67716.9 | IM5: 67725.6 | IN5: 67733.9 | IO5: 67740.1 | IP5: 67764.6 | IQ5: 67781.5 | IR5: 67796.4 | IS5: 67806.6 | IT5: 67814.9 | IU5: 67833 | IV5: 67848.4 | IW5: 67865.7 | IX5: 67876.1 | IY5: 67886.4 | IZ5: 67901.5 | JA5: 67910.1 | JB5: 67926.2 | JC5: 67937.5 | JD5: 67951.2 | JE5: 67970.1 | JF5: 67988.5 | JG5: 68008.6 | JH5: 68017.4 | JI5: 68048.1 | JJ5: 68077.7 | JK5: 68107.8 | JL5: 68133.9 | JM5: 68159.8 | JN5: 68183 | JO5: 68192.3 | JP5: 68221.9 | JQ5: 68247.8 | JR5: 68275.8 | JS5: 68287.8 | JT5: 68304.7 | JU5: 68319 | JV5: 68327.3 | JW5: 68345.8 | JX5: 68360.2 | JY5: 68382.2 | JZ5: 68398.3 | KA5: 68418.5 | KB5: 68431.8 | KC5: 68443.5 | KD5: 68454.4 | KE5: 68469 | KF5: 68478.9 | KG5: 68514.7 | KH5: 68525.1 | KI5: 68537.8 | KJ5: 68546.5 | KK5: 68579.7 | KL5: 68593.7 | KM5: 68608.4 | KN5: 68624.5 | KO5: 68649.1 | KP5: 68672 | KQ5: 68680.1 | KR5: 68714.2 | KS5: 68743.2 | KT5: 68775.7 | KU5: 68808.5 | KV5: 68821.1 | KW5: 68834.4 | KX5: 68842.8 | KY5: 68865.6 | KZ5: 68885.5 | LA5: 68897.9 | LB5: 68909 | LC5: 68934 | LD5: 68957.3 | LE5: 68961.6 | LF5: 68975.8 | LG5: 68986.4 | LH5: 68999.5 | LI5: 69016.3 | LJ5: 69040.7 | LK5: 69053.7 | LL5: 69062.2 | LM5: 69077.6 | LN5: 69098.4 | LO5: 69129.3 | LP5: 69160 | LQ5: 69179.9 | LR5: 69191.7 | LS5: 69199.5 | LT5: 69229.2 | LU5: 69243 | LV5: 69259.2 | LW5: 69276.1 | LX5: 69287.5 | LY5: 69299.4 | LZ5: 69308.5 | MA5: 69320.1 | MB5: 69344.9 | MC5: 69365.1 | MD5: 69374.8 | ME5: 69386.1 | MF5: 69399.4 | MG5: 69409 | MH5: 69420.2 | MI5: 69430.8 | MJ5: 69461.3 | MK5: 69492.4 | ML5: 69509.4 | MM5: 69523.7 | MN5: 69533.1 | MO5: 69544.1 | MP5: 69556.1 | MQ5: 69566.2 | MR5: 69590.9 | MS5: 69602.3 | MT5: 69614.5 | MU5: 69623.7 | MV5: 69639.8 | MW5: 69654.3 | MX5: 69665.9 | MY5: 69680.6 | MZ5: 69690.5 | NA5: 69699.6 | NB5: 69707.6 | NC5: 69718.8 | ND5: 69751.1 | NE5: 69771.5 | NF5: 69781.8 | NG5: 69812.3 | NH5: 69837.3 | NI5: 69845.4 | NJ5: 69856.7 | NK5: 69875.5 | NL5: 69900.6 | NM5: 69940.7 | NN5: 69961.9 | NO5: 69971.3 | NP5: 69980.5 | NQ5: 70004.6 | NR5: 70027.9 | NS5: 70058.7 | NT5: 70083.5 | NU5: 70110.9 | NV5: 70127.3 | NW5: 70134.8 | NX5: 70147.3 | NY5: 70159.4 | NZ5: 70175.8 | OA5: 70192.7 | OB5: 70209.4 | OC5: 70219.4 | OD5: 70231.5 | OE5: 70246.3 | OF5: 70263.7 | OG5: 70282 | OH5: 70303.1 | OI5: 70328.2 | OJ5: 70353.5 | OK5: 70364.5 | OL5: 70381.1 | OM5: 70405.6 | ON5: 70419.9 | OO5: 70436.1 | OP5: 70462.4 | OQ5: 70474.2 | OR5: 70484.9 | OS5: 70510.9 | OT5: 70547.5 | OU5: 70580.8 | OV5: 70618.6 | OW5: 70644.4 | OX5: 70655.9 | OY5: 70665.3 | OZ5: 70674.6 | PA5: 70683.9 | PB5: 70693.2 | PC5: 70702.5 | PD5: 70711.9 | PE5: 70721.2 | PF5: 70730.8 | PG5: 70745.5 | PH5: 70778.1 | PI5: 70791.1 | PJ5: 70827.9 | PK5: 70848.1 | PL5: 70867.8 | PM5: 70883 | PN5: 70919.7 | PO5: 70962 | PP5: 71005.4 | PQ5: 71051.1 | PR5: 71084.8 | PS5: 71124.4 | PT5: 71135.6 | PU5: 71178.2 | PV5: 71217.6 | PW5: 71262.9 | PX5: 71292.1 | PY5: 71323 | PZ5: 71344.5 | QA5: 71357.6 | QB5: 71399.2 | QC5: 71443.5 | QD5: 71483.6 | QE5: 71521.7 | QF5: 71563.9 | QG5: 71615.4 | QH5: 71646.9 | QI5: 71686 | QJ5: 71733 | QK5: 71776.3 | QL5: 71816 | QM5: 71863.5 | QN5: 71892.2 | QO5: 71903.5 | QP5: 71936.7 | QQ5: 71977.1 | QR5: 72019.7 | QS5: 72047.8 | QT5: 72082.8 | QU5: 72093.2 | QV5: 72107.9 | QW5: 72151.8 | QX5: 72194.3 | QY5: 72238.4 | QZ5: 72279.6 | RA5: 72323.9 | RB5: 72354.1 | RC5: 72366.1 | RD5: 72401.9 | RE5: 72452.7 | RF5: 72496.2 | RG5: 72540.9 | RH5: 72580.9 | RI5: 72592.5 | RJ5: 72604.2 | RK5: 72647.6 | RL5: 72690.5 | RM5: 72734.5 | RN5: 72767.6 | RO5: 72810.7 | RP5: 72846.3 | RQ5: 72859.6 | RR5: 72874.5 | RS5: 72916.1 | RT5: 72938.1 | RU5: 72947.7 | RV5: 72957.8 | RW5: 72968.2 | RX5: 72980.3 | RY5: 73015.4 | RZ5: 73064 | SA5: 73106.7 | SB5: 73149.8 | SC5: 73192.4 | SD5: 73227.8 | SE5: 73246.1 | SF5: 73290.4 | SG5: 73333.8 | SH5: 73379.5 | SI5: 73422.8 | SJ5: 73456.2 | SK5: 73492.7 | SL5: 73504 | SM5: 73542.9 | SN5: 73585.5 | SO5: 73635.4 | SP5: 73677.8 | SQ5: 73722.9 | SR5: 73769.3 | SS5: 73784.3 | ST5: 73823.7 | SU5: 73864 | SV5: 73905.6 | SW5: 73950.7 | SX5: 73994.8 | SY5: 74005.9 | SZ5: 74017.2 | TA5: 74056.6 | TB5: 74095.2 | TC5: 74137.8 | TD5: 74182.8 | TE5: 74229 | TF5: 74269.4 | TG5: 74284.6 | TH5: 74330.4 | TI5: 74376.2 | TJ5: 74420.1 | TK5: 74459.7 | TL5: 74498.4 | TM5: 74543.4 | TN5: 74556.1 | TO5: 74606.7
C6: F1EL12 | D6: 41530.8 | E6: 41553.4 | F6: 41578 | G6: 41614.5 | H6: 41651.1 | I6: 41654.8 | J6: 41699.6 | K6: 41742.2 | L6: 41769.7 | M6: 41809.8 | N6: 41844.6 | O6: 41871.6 | P6: 41899.4 | Q6: 41945.4 | R6: 41984 | S6: 42032.7 | T6: 42078.6 | U6: 42113.4 | V6: 42147 | W6: 42149.6 | X6: 42190.7 | Y6: 42240.9 | Z6: 42285 | AA6: 42316.1 | AB6: 42353.2 | AC6: 42384.2 | AD6: 42387.7 | AE6: 42391.2 | AF6: 42394.7 | AG6: 42398.2 | AH6: 42401.6 | AI6: 42405.1 | AJ6: 42408.5 | AK6: 42413 | AL6: 42454.5 | AM6: 42491.4 | AN6: 42528.5 | AO6: 42566.8 | AP6: 42599.2 | AQ6: 42627.2 | AR6: 42631.2 | AS6: 42670.5 | AT6: 42713.9 | AU6: 42753 | AV6: 42791.4 | AW6: 42821.7 | AX6: 42851 | AY6: 42855.1 | AZ6: 42890.4 | BA6: 42932 | BB6: 42978.9 | BC6: 43020.6 | BD6: 43053.3 | BE6: 43089.7 | BF6: 43097.9 | BG6: 43138.3 | BH6: 43184.2 | BI6: 43223.4 | BJ6: 43269.5 | BK6: 43301 | BL6: 43331.6 | BM6: 43335.8 | BN6: 43386.6 | BO6: 43422.4 | BP6: 43456.3 | BQ6: 43490.7 | BR6: 43520.8 | BS6: 43556.5 | BT6: 43560.7 | BU6: 43595.6 | BV6: 43629.7 | BW6: 43668.1 | BX6: 43704.8 | BY6: 43740.2 | BZ6: 43772.5 | CA6: 43778.1 | CB6: 43811.8 | CC6: 43851.9 | CD6: 43906.1 | CE6: 43950.9 | CF6: 43997.2 | CG6: 44031.4 | CH6: 44036.7 | CI6: 44084.9 | CJ6: 44136.8 | CK6: 44184.4 | CL6: 44234 | CM6: 44269.1 | CN6: 44298.6 | CO6: 44304.1 | CP6: 44350.7 | CQ6: 44399 | CR6: 44445.1 | CS6: 44480.5 | CT6: 44511 | CU6: 44525.9 | CV6: 44530.2 | CW6: 44534.8 | CX6: 44556.7 | CY6: 44580.7 | CZ6: 44611.5 | DA6: 44619.6 | DB6: 44633.2 | DC6: 44637.8 | DD6: 44659.7 | DE6: 44685.9 | DF6: 44698.4 | DG6: 44717.1 | DH6: 44731.9 | DI6: 44741.4 | DJ6: 44745.9 | DK6: 44773 | DL6: 44795.5 | DM6: 44811.7 | DN6: 44819.9 | DO6: 44828.5 | DP6: 44836.6 | DQ6: 44842 | DR6: 44868.4 | DS6: 44874.4 | DT6: 44891.1 | DU6: 44895.9 | DV6: 44913.3 | DW6: 44941.7 | DX6: 44955.3 | DY6: 44968.5 | DZ6: 44978.2 | EA6: 44992.6 | EB6: 44999.1 | EC6: 45020.3 | ED6: 45034.4 | EE6: 45054 | EF6: 45075.9 | EG6: 45109.1 | EH6: 45127.6 | EI6: 45146.7 | EJ6: 45177.8 | EK6: 45207 | EL6: 45233.5 | EM6: 45258.7 | EN6: 45276.1 | EO6: 45293.6 | EP6: 45310.3 | EQ6: 45330.3 | ER6: 45357.9 | ES6: 45359.8 | ET6: 45386.4 | EU6: 45421.6 | EV6: 45449.5 | EW6: 45491.5 | EX6: 45528.8 | EY6: 45556.5 | EZ6: 45590.3 | FA6: 45617.6 | FB6: 45644 | FC6: 45702.1 | FD6: 45751.2 | FE6: 45776.4 | FF6: 45803.9 | FG6: 45834.6 | FH6: 45866.7 | FI6: 45898.1 | FJ6: 45948.6 | FK6: 45983.4 | FL6: 46033.7 | FM6: 46066.4 | FN6: 46070.7 | FO6: 46124.1 | FP6: 46193.3 | FQ6: 46260 | FR6: 46321.4 | FS6: 46353.2 | FT6: 46409.4 | FU6: 46417.4 | FV6: 46471.3 | FW6: 46518.1 | FX6: 46571.3 | FY6: 46615.7 | FZ6: 46660.1 | GA6: 46700 | GB6: 46704.3 | GC6: 46750.3 | GD6: 46800.1 | GE6: 46830.6 | GF6: 46855 | GG6: 46880.5 | GH6: 46918.5 | GI6: 46933.6 | GJ6: 46957 | GK6: 46981.3 | GL6: 47002.3 | GM6: 47028.6 | GN6: 47061.6 | GO6: 47102.2 | GP6: 47107.6 | GQ6: 47132.8 | GR6: 47153.8 | GS6: 47183.4 | GT6: 47211.5 | GU6: 47230.3 | GV6: 47251 | GW6: 47256.4 | GX6: 47268.8 | GY6: 47274.2 | GZ6: 47294.2 | HA6: 47304.4 | HB6: 47322.1 | HC6: 47355.2 | HD6: 47361.5 | HE6: 47395 | HF6: 47427.6 | HG6: 47465.5 | HH6: 47498.2 | HI6: 47515.2 | HJ6: 47531.1 | HK6: 47537.4 | HL6: 47560.2 | HM6: 47573 | HN6: 47585.7 | HO6: 47592.2 | HP6: 47616.2 | HQ6: 47628.5 | HR6: 47633.9 | HS6: 47649.4 | HT6: 47658.3 | HU6: 47668.1 | HV6: 47673.6 | HW6: 47679.3 | HX6: 47688.2 | HY6: 47693.6 | HZ6: 47712.3 | IA6: 47719.2 | IB6: 47729.7 | IC6: 47740.3 | ID6: 47751.5 | IE6: 47763.2 | IF6: 47768.6 | IG6: 47783.7 | IH6: 47792.8 | II6: 47815.3 | IJ6: 47838.1 | IK6: 47869.5 | IL6: 47890.7 | IM6: 47896.1 | IN6: 47901.5 | IO6: 47906 | IP6: 47917.9 | IQ6: 47937.8 | IR6: 47952.4 | IS6: 47964.7 | IT6: 47970.3 | IU6: 47993 | IV6: 48007.7 | IW6: 48024 | IX6: 48041.9 | IY6: 48046.3 | IZ6: 48056.6 | JA6: 48060.9 | JB6: 48066.8 | JC6: 48073.5 | JD6: 48100.7 | JE6: 48111.8 | JF6: 48138.6 | JG6: 48155.7 | JH6: 48160.4 | JI6: 48195.7 | JJ6: 48224.6 | JK6: 48251.6 | JL6: 48280.2 | JM6: 48307.2 | JN6: 48337.6 | JO6: 48358.8 | JP6: 48384.8 | JQ6: 48421.2 | JR6: 48454.4 | JS6: 48488.5 | JT6: 48523.2 | JU6: 48545 | JV6: 48549.6 | JW6: 48559 | JX6: 48578.2 | JY6: 48589.1 | JZ6: 48593.6 | KA6: 48613.9 | KB6: 48621 | KC6: 48625.3 | KD6: 48634.5 | KE6: 48651.9 | KF6: 48660 | KG6: 48672.7 | KH6: 48697.3 | KI6: 48721.9 | KJ6: 48726.2 | KK6: 48758.4 | KL6: 48769.3 | KM6: 48780.4 | KN6: 48800.2 | KO6: 48828.9 | KP6: 48857.7 | KQ6: 48862.5 | KR6: 48894 | KS6: 48924.9 | KT6: 48951.8 | KU6: 48964 | KV6: 48986.9 | KW6: 49007.4 | KX6: 49012 | KY6: 49027.7 | KZ6: 49042.1 | LA6: 49050.1 | LB6: 49056.5 | LC6: 49078.1 | LD6: 49094 | LE6: 49096.9 | LF6: 49113.1 | LG6: 49130.1 | LH6: 49153.1 | LI6: 49177.1 | LJ6: 49197.1 | LK6: 49214.4 | LL6: 49219 | LM6: 49231.7 | LN6: 49239.3 | LO6: 49255.2 | LP6: 49277 | LQ6: 49281.4 | LR6: 49287 | LS6: 49291.3 | LT6: 49315.4 | LU6: 49319.8 | LV6: 49324.2 | LW6: 49328.7 | LX6: 49346.2 | LY6: 49366.7 | LZ6: 49371 | MA6: 49375.5 | MB6: 49382.9 | MC6: 49387.5 | MD6: 49391.9 | ME6: 49396.3 | MF6: 49400.7 | MG6: 49408 | MH6: 49413 | MI6: 49423 | MJ6: 49447.6 | MK6: 49472.4 | ML6: 49497.7 | MM6: 49514 | MN6: 49518.4 | MO6: 49539.8 | MP6: 49545.9 | MQ6: 49565.5 | MR6: 49570.4 | MS6: 49574.9 | MT6: 49579.3 | MU6: 49583.6 | MV6: 49588.1 | MW6: 49593.4 | MX6: 49604.2 | MY6: 49614.6 | MZ6: 49624.9 | NA6: 49630.1 | NB6: 49635.7 | NC6: 49646.6 | ND6: 49658.3 | NE6: 49677 | NF6: 49696.3 | NG6: 49724.2 | NH6: 49755.8 | NI6: 49766.9 | NJ6: 49800.2 | NK6: 49805.5 | NL6: 49811 | NM6: 49826.3 | NN6: 49843.5 | NO6: 49863.7 | NP6: 49883.1 | NQ6: 49917.1 | NR6: 49946.2 | NS6: 49967.8 | NT6: 49985.1 | NU6: 50009.3 | NV6: 50043.1 | NW6: 50048.3 | NX6: 50071 | NY6: 50120.8 | NZ6: 50142.1 | OA6: 50148.1 | OB6: 50153.5 | OC6: 50158.8 | OD6: 50164 | OE6: 50184.3 | OF6: 50208.3 | OG6: 50227.3 | OH6: 50233.7 | OI6: 50246.1 | OJ6: 50267.7 | OK6: 50285.4 | OL6: 50309.8 | OM6: 50332 | ON6: 50356.8 | OO6: 50362.5 | OP6: 50371.8 | OQ6: 50380.5 | OR6: 50383.5 | OS6: 50389.8 | OT6: 50398.4 | OU6: 50410.1 | OV6: 50428.4 | OW6: 50443.4 | OX6: 50451 | OY6: 50456.2 | OZ6: 50461.4 | PA6: 50466.5 | PB6: 50471.7 | PC6: 50476.8 | PD6: 50482.5 | PE6: 50488.8 | PF6: 50495.2 | PG6: 50506.9 | PH6: 50533 | PI6: 50562.1 | PJ6: 50588.1 | PK6: 50605.5 | PL6: 50639.3 | PM6: 50667 | PN6: 50690.5 | PO6: 50723.1 | PP6: 50767.5 | PQ6: 50803.3 | PR6: 50836.4 | PS6: 50876.2 | PT6: 50880.5 | PU6: 50915.7 | PV6: 50952.4 | PW6: 50988.5 | PX6: 51029.9 | PY6: 51062.5 | PZ6: 51079.3 | QA6: 51107.8 | QB6: 51146.6 | QC6: 51186.8 | QD6: 51221.6 | QE6: 51264 | QF6: 51307.5 | QG6: 51346.3 | QH6: 51351.6 | QI6: 51385.1 | QJ6: 51412.7 | QK6: 51435.1 | QL6: 51471.6 | QM6: 51508.2 | QN6: 51537 | QO6: 51542.3 | QP6: 51585.6 | QQ6: 51622.9 | QR6: 51660.2 | QS6: 51696.5 | QT6: 51727.4 | QU6: 51734.3 | QV6: 51738.7 | QW6: 51769.3 | QX6: 51811.4 | QY6: 51848.4 | QZ6: 51883.2 | RA6: 51926.4 | RB6: 51954.5 | RC6: 51960 | RD6: 51995.2 | RE6: 52028.4 | RF6: 52070.4 | RG6: 52112.7 | RH6: 52136.2 | RI6: 52156.8 | RJ6: 52167.2 | RK6: 52190.3 | RL6: 52213.2 | RM6: 52253.6 | RN6: 52289 | RO6: 52310.8 | RP6: 52325.2 | RQ6: 52329.5 | RR6: 52333.8 | RS6: 52350.7 | RT6: 52374.2 | RU6: 52378.5 | RV6: 52382.9 | RW6: 52387.2 | RX6: 52391.7 | RY6: 52427.3 | RZ6: 52457 | SA6: 52491.9 | SB6: 52524.5 | SC6: 52546.2 | SD6: 52563.7 | SE6: 52596.4 | SF6: 52628.5 | SG6: 52663.8 | SH6: 52703 | SI6: 52724.7 | SJ6: 52743.7 | SK6: 52759.4 | SL6: 52764.5 | SM6: 52798.5 | SN6: 52831.6 | SO6: 52871.7 | SP6: 52914.1 | SQ6: 52954.8 | SR6: 52992.1 | SS6: 52998.3 | ST6: 53038.8 | SU6: 53081.6 | SV6: 53108.4 | SW6: 53145.9 | SX6: 53176.1 | SY6: 53211.5 | SZ6: 53216.7 | TA6: 53260.5 | TB6: 53299.1 | TC6: 53321.2 | TD6: 53363.1 | TE6: 53402 | TF6: 53419 | TG6: 53424.3 | TH6: 53441.3 | TI6: 53486.6 | TJ6: 53502.7 | TK6: 53528.9 | TL6: 53568.6 | TM6: 53587.5 | TN6: 53592.6 | TO6: 53629.5
C7: F1PZ11 | D7: 22181 | E7: 22194 | F7: 22213.4 | G7: 22232.4 | H7: 22250 | I7: 22261.9 | J7: 22282.6 | K7: 22302.3 | L7: 22321.5 | M7: 22342.8 | N7: 22363.9 | O7: 22384.4 | P7: 22394 | Q7: 22420.3 | R7: 22440 | S7: 22456 | T7: 22486.8 | U7: 22508.9 | V7: 22537.9 | W7: 22552.4 | X7: 22583.7 | Y7: 22616.9 | Z7: 22643.1 | AA7: 22674.8 | AB7: 22697.8 | AC7: 22726.6 | AD7: 22750.5 | AE7: 22765.2 | AF7: 22776 | AG7: 22787.6 | AH7: 22799 | AI7: 22807.9 | AJ7: 22817.3 | AK7: 22827.2 | AL7: 22860.2 | AM7: 22890.1 | AN7: 22915.4 | AO7: 22943.6 | AP7: 22970.8 | AQ7: 23002.3 | AR7: 23015.4 | AS7: 23050.6 | AT7: 23081.7 | AU7: 23114 | AV7: 23138.5 | AW7: 23164.6 | AX7: 23188.4 | AY7: 23201.9 | AZ7: 23225.8 | BA7: 23248.4 | BB7: 23283 | BC7: 23309.3 | BD7: 23334.5 | BE7: 23360.1 | BF7: 23372.2 | BG7: 23394.5 | BH7: 23422 | BI7: 23443.7 | BJ7: 23472.5 | BK7: 23497.5 | BL7: 23528.2 | BM7: 23540.8 | BN7: 23583.6 | BO7: 23625.5 | BP7: 23661.4 | BQ7: 23705.6 | BR7: 23746.7 | BS7: 23789.2 | BT7: 23819.3 | BU7: 23874.8 | BV7: 23913.6 | BW7: 23957.7 | BX7: 23995.9 | BY7: 24037.1 | BZ7: 24078.7 | CA7: 24108 | CB7: 24138.7 | CC7: 24182 | CD7: 24227.9 | CE7: 24266.2 | CF7: 24311.4 | CG7: 24361.5 | CH7: 24375.5 | CI7: 24420.6 | CJ7: 24474.5 | CK7: 24511.1 | CL7: 24555.8 | CM7: 24594.1 | CN7: 24636.8 | CO7: 24664.4 | CP7: 24707.2 | CQ7: 24763.8 | CR7: 24816.8 | CS7: 24855.2 | CT7: 24889.4 | CU7: 24921.3 | CV7: 24930.3 | CW7: 24947.8 | CX7: 24991.6 | CY7: 25033.5 | CZ7: 25070.1 | DA7: 25106.5 | DB7: 25149.3 | DC7: 25160.8 | DD7: 25196.8 | DE7: 25230.2 | DF7: 25264.2 | DG7: 25297.6 | DH7: 25342.4 | DI7: 25391.4 | DJ7: 25401.6 | DK7: 25435.3 | DL7: 25477.2 | DM7: 25504.4 | DN7: 25536.3 | DO7: 25584.9 | DP7: 25615.4 | DQ7: 25631.3 | DR7: 25665.9 | DS7: 25706.5 | DT7: 25722 | DU7: 25732.7 | DV7: 25785.8 | DW7: 25814.3 | DX7: 25837.5 | DY7: 25878.2 | DZ7: 25935.1 | EA7: 25985.8 | EB7: 26010 | EC7: 26063.5 | ED7: 26096.4 | EE7: 26107.3 | EF7: 26169.1 | EG7: 26212.9 | EH7: 26251.1 | EI7: 26308.4 | EJ7: 26346.5 | EK7: 26402.8 | EL7: 26428.6 | EM7: 26485.5 | EN7: 26528.4 | EO7: 26580.7 | EP7: 26629.4 | EQ7: 26698.8 | ER7: 26733.6 | ES7: 26745.5 | ET7: 26780.1 | EU7: 26875.9 | EV7: 26912.2 | EW7: 26967.1 | EX7: 27023.4 | EY7: 27082.4 | EZ7: 27100.6 | FA7: 27146.4 | FB7: 27192.3 | FC7: 27244.6 | FD7: 27274.3 | FE7: 27320.9 | FF7: 27353.9 | FG7: 27366.8 | FH7: 27418.9 | FI7: 27455.2 | FJ7: 27506 | FK7: 27555 | FL7: 27586.5 | FM7: 27629.8 | FN7: 27637.3 | FO7: 27677.3 | FP7: 27723.5 | FQ7: 27782.7 | FR7: 27817.9 | FS7: 27877.9 | FT7: 27924.6 | FU7: 27935 | FV7: 27988.1 | FW7: 28026.3 | FX7: 28080.1 | FY7: 28112.2 | FZ7: 28144.2 | GA7: 28174.1 | GB7: 28188.2 | GC7: 28255.6 | GD7: 28293.9 | GE7: 28341.7 | GF7: 28386.2 | GG7: 28452.4 | GH7: 28501.4 | GI7: 28510.4 | GJ7: 28572.9 | GK7: 28621.1 | GL7: 28678 | GM7: 28692.9 | GN7: 28741.7 | GO7: 28765.5 | GP7: 28771.9 | GQ7: 28809.6 | GR7: 28844.7 | GS7: 28891.4 | GT7: 28930.1 | GU7: 28969.6 | GV7: 28989 | GW7: 28998.4 | GX7: 29023.5 | GY7: 29030.5 | GZ7: 29059.4 | HA7: 29088.8 | HB7: 29113.6 | HC7: 29141 | HD7: 29147.4 | HE7: 29177.2 | HF7: 29209.8 | HG7: 29250.6 | HH7: 29280.3 | HI7: 29307.4 | HJ7: 29337 | HK7: 29344.3 | HL7: 29386 | HM7: 29417.4 | HN7: 29445.8 | HO7: 29469.8 | HP7: 29495.1 | HQ7: 29513.7 | HR7: 29519.7 | HS7: 29545.8 | HT7: 29572.1 | HU7: 29595.5 | HV7: 29619.4 | HW7: 29641.4 | HX7: 29661.6 | HY7: 29669.6 | HZ7: 29696.6 | IA7: 29720.5 | IB7: 29749.4 | IC7: 29775.4 | ID7: 29800 | IE7: 29823.4 | IF7: 29834.5 | IG7: 29866.3 | IH7: 29891.3 | II7: 29915.2 | IJ7: 29945.2 | IK7: 29968.2 | IL7: 29986.3 | IM7: 30001.3 | IN7: 30009.5 | IO7: 30018.4 | IP7: 30041.7 | IQ7: 30069 | IR7: 30094.9 | IS7: 30117.4 | IT7: 30125.8 | IU7: 30150.9 | IV7: 30174.8 | IW7: 30199.2 | IX7: 30222.1 | IY7: 30245.2 | IZ7: 30266.4 | JA7: 30277.6 | JB7: 30300.5 | JC7: 30323.2 | JD7: 30347.7 | JE7: 30373.6 | JF7: 30395.9 | JG7: 30418.7 | JH7: 30433 | JI7: 30456.8 | JJ7: 30480.8 | JK7: 30504 | JL7: 30528.2 | JM7: 30553.4 | JN7: 30574.6 | JO7: 30585.3 | JP7: 30609.2 | JQ7: 30634 | JR7: 30658.6 | JS7: 30682 | JT7: 30704.5 | JU7: 30724.9 | JV7: 30735.5 | JW7: 30758.5 | JX7: 30781.4 | JY7: 30807.4 | JZ7: 30830.7 | KA7: 30862.5 | KB7: 30887.2 | KC7: 30898.6 | KD7: 30932.7 | KE7: 30957.4 | KF7: 30982.9 | KG7: 31008.4 | KH7: 31041.2 | KI7: 31063.5 | KJ7: 31082 | KK7: 31115.5 | KL7: 31150.8 | KM7: 31172.2 | KN7: 31190.3 | KO7: 31210.6 | KP7: 31233.2 | KQ7: 31242.8 | KR7: 31266 | KS7: 31299.4 | KT7: 31326.3 | KU7: 31350.5 | KV7: 31374.8 | KW7: 31409.4 | KX7: 31435.5 | KY7: 31466 | KZ7: 31492.6 | LA7: 31519.6 | LB7: 31546.8 | LC7: 31578 | LD7: 31597.5 | LE7: 31604.3 | LF7: 31643.6 | LG7: 31666.1 | LH7: 31689.4 | LI7: 31713 | LJ7: 31736.2 | LK7: 31755.9 | LL7: 31766.7 | LM7: 31789.3 | LN7: 31809.7 | LO7: 31819.9 | LP7: 31832.6 | LQ7: 31853.7 | LR7: 31864.4 | LS7: 31875.4 | LT7: 31900.7 | LU7: 31926.7 | LV7: 31952.8 | LW7: 31977.6 | LX7: 32003.5 | LY7: 32023.2 | LZ7: 32035.1 | MA7: 32058.5 | MB7: 32084.6 | MC7: 32109.1 | MD7: 32131.8 | ME7: 32154.2 | MF7: 32173.8 | MG7: 32184.9 | MH7: 32210.9 | MI7: 32238.2 | MJ7: 32263.6 | MK7: 32289.3 | ML7: 32309.9 | MM7: 32324.5 | MN7: 32334 | MO7: 32369.7 | MP7: 32403.6 | MQ7: 32419.7 | MR7: 32443.8 | MS7: 32472.7 | MT7: 32489.6 | MU7: 32498.5 | MV7: 32524.1 | MW7: 32554.8 | MX7: 32579.5 | MY7: 32601.1 | MZ7: 32622.9 | NA7: 32641.9 | NB7: 32654.2 | NC7: 32684.4 | ND7: 32711.1 | NE7: 32723.8 | NF7: 32735.9 | NG7: 32773.2 | NH7: 32792.7 | NI7: 32804 | NJ7: 32833.4 | NK7: 32860.1 | NL7: 32888.4 | NM7: 32920.5 | NN7: 32944.8 | NO7: 32953.8 | NP7: 32966.7 | NQ7: 33006.8 | NR7: 33030 | NS7: 33050.8 | NT7: 33066.6 | NU7: 33094.4 | NV7: 33119.9 | NW7: 33133.5 | NX7: 33155.9 | NY7: 33175 | NZ7: 33196.4 | OA7: 33219.4 | OB7: 33234.3 | OC7: 33243.2 | OD7: 33252.5 | OE7: 33275.6 | OF7: 33290.9 | OG7: 33308.3 | OH7: 33331.3 | OI7: 33348.1 | OJ7: 33362.1 | OK7: 33373.5 | OL7: 33393.8 | OM7: 33414.4 | ON7: 33453.2 | OO7: 33473.8 | OP7: 33490.2 | OQ7: 33499.1 | OR7: 33512.1 | OS7: 33538.2 | OT7: 33559 | OU7: 33582.8 | OV7: 33605.1 | OW7: 33628 | OX7: 33639 | OY7: 33639 | OZ7: 33639 | PA7: 33639 | PB7: 33639 | PC7: 33639 | PD7: 33639 | PE7: 33639 | PF7: 33640.4 | PG7: 33688.8 | PH7: 33713 | PI7: 33734.4 | PJ7: 33756.6 | PK7: 33782.7 | PL7: 33812.8 | PM7: 33833.7 | PN7: 33862.2 | PO7: 33889.4 | PP7: 33919.2 | PQ7: 33951.4 | PR7: 33968.3 | PS7: 33978.5 | PT7: 33991.5 | PU7: 34019.7 | PV7: 34050 | PW7: 34087.9 | PX7: 34120.6 | PY7: 34146.2 | PZ7: 34166.1 | QA7: 34179.4 | QB7: 34215.3 | QC7: 34242.1 | QD7: 34266.8 | QE7: 34293 | QF7: 34335.2 | QG7: 34367 | QH7: 34380.2 | QI7: 34407.4 | QJ7: 34451 | QK7: 34476.2 | QL7: 34501.9 | QM7: 34543 | QN7: 34561.8 | QO7: 34573.2 | QP7: 34598.6 | QQ7: 34638.9 | QR7: 34664.5 | QS7: 34688.3 | QT7: 34713.8 | QU7: 34724.2 | QV7: 34738.2 | QW7: 34777.9 | QX7: 34820 | QY7: 34850.3 | QZ7: 34875.1 | RA7: 34905.2 | RB7: 34930.5 | RC7: 34953.3 | RD7: 34998.9 | RE7: 35036.2 | RF7: 35067.6 | RG7: 35103.3 | RH7: 35128.8 | RI7: 35138.1 | RJ7: 35150.8 | RK7: 35176 | RL7: 35206.5 | RM7: 35231.1 | RN7: 35271.7 | RO7: 35312.6 | RP7: 35336.6 | RQ7: 35350.3 | RR7: 35365.4 | RS7: 35402.2 | RT7: 35428 | RU7: 35440.7 | RV7: 35455.4 | RW7: 35469.1 | RX7: 35483.2 | RY7: 35513.3 | RZ7: 35535.4 | SA7: 35556.7 | SB7: 35579 | SC7: 35601.1 | SD7: 35626 | SE7: 35647.2 | SF7: 35694.9 | SG7: 35728.3 | SH7: 35759.2 | SI7: 35789.4 | SJ7: 35841.2 | SK7: 35866.6 | SL7: 35876.4 | SM7: 35901.6 | SN7: 35917.7 | SO7: 35967.3 | SP7: 36014.4 | SQ7: 36045.2 | SR7: 36068.3 | SS7: 36079.2 | ST7: 36127.4 | SU7: 36153.8 | SV7: 36193 | SW7: 36233.3 | SX7: 36271.8 | SY7: 36285.1 | SZ7: 36295.3 | TA7: 36337.9 | TB7: 36377.7 | TC7: 36409.9 | TD7: 36435.7 | TE7: 36476.3 | TF7: 36500.8 | TG7: 36510.5 | TH7: 36562.2 | TI7: 36593.4 | TJ7: 36626.8 | TK7: 36669.9 | TL7: 36702.6 | TM7: 36743.4 | TN7: 36765.4 | TO7: 36797.1
